ProgrammingError
sqlalchemy.exc.ProgrammingError: (psycopg2.errors.UndefinedColumn) column teacher.user_id does not exist
LINE 2: ...ne, teacher.observations AS teacher_observations, teacher.us...
                                                             ^

[SQL: SELECT count(*) AS count_1 
FROM (SELECT teacher.id AS teacher_id, teacher.name AS teacher_name, teacher.area AS teacher_area, teacher.subjects AS teacher_subjects, teacher.workload AS teacher_workload, teacher.email AS teacher_email, teacher.phone AS teacher_phone, teacher.observations AS teacher_observations, teacher.user_id AS teacher_user_id, teacher.created_at AS teacher_created_at 
FROM teacher) AS anon_1]
(Background on this error at: https://sqlalche.me/e/20/f405)

Traceback (most recent call last)
This is the Copy/Paste friendly version of the traceback.

Traceback (most recent call last):
  File "/opt/venv/lib/python3.12/site-packages/sqlalchemy/engine/base.py", line 1967, in _exec_single_context
    self.dialect.do_execute(
  File "/opt/venv/lib/python3.12/site-packages/sqlalchemy/engine/default.py", line 951, in do_execute
    cursor.execute(statement, parameters)
psycopg2.errors.UndefinedColumn: column teacher.user_id does not exist
LINE 2: ...ne, teacher.observations AS teacher_observations, teacher.us...
                                                             ^


The above exception was the direct cause of the following exception:

Traceback (most recent call last):
  File "/opt/venv/lib/python3.12/site-packages/flask/app.py", line 1536, in __call__
    return self.wsgi_app(environ, start_response)
           ^^^^^^^^^^^^^^^^^^^^^^^^^^^^^^^^^^^^^^
  File "/opt/venv/lib/python3.12/site-packages/werkzeug/middleware/proxy_fix.py", line 183, in __call__
    return self.app(environ, start_response)
           ^^^^^^^^^^^^^^^^^^^^^^^^^^^^^^^^^
  File "/opt/venv/lib/python3.12/site-packages/flask/app.py", line 1514, in wsgi_app
    response = self.handle_exception(e)
               ^^^^^^^^^^^^^^^^^^^^^^^^
  File "/opt/venv/lib/python3.12/site-packages/flask/app.py", line 1511, in wsgi_app
    response = self.full_dispatch_request()
               ^^^^^^^^^^^^^^^^^^^^^^^^^^^^
  File "/opt/venv/lib/python3.12/site-packages/flask/app.py", line 919, in full_dispatch_request
    rv = self.handle_user_exception(e)
         ^^^^^^^^^^^^^^^^^^^^^^^^^^^^^
  File "/opt/venv/lib/python3.12/site-packages/flask/app.py", line 917, in full_dispatch_request
    rv = self.dispatch_request()
         ^^^^^^^^^^^^^^^^^^^^^^^
  File "/opt/venv/lib/python3.12/site-packages/flask/app.py", line 902, in dispatch_request
    return self.ensure_sync(self.view_functions[rule.endpoint])(**view_args)  # type: ignore[no-any-return]
           ^^^^^^^^^^^^^^^^^^^^^^^^^^^^^^^^^^^^^^^^^^^^^^^^^^^^^^^^^^^^^^^^^^^^^^^^^^^^^^^^^^^^^^^^^^^^^^^^
  File "/opt/venv/lib/python3.12/site-packages/flask_login/utils.py", line 290, in decorated_view
    return current_app.ensure_sync(func)(*args, **kwargs)
           ^^^^^^^^^^^^^^^^^^^^^^^^^^^^^^^^^^^^^^^^^^^^^^
  File "/app/routes.py", line 41, in index
    total_teachers = Teacher.query.count()
                     ^^^^^^^^^^^^^^^^^^^^^
  File "/opt/venv/lib/python3.12/site-packages/sqlalchemy/orm/query.py", line 3146, in count
    self._legacy_from_self(col).enable_eagerloads(False).scalar()
  File "/opt/venv/lib/python3.12/site-packages/sqlalchemy/orm/query.py", line 2835, in scalar
    ret = self.one()
          ^^^^^^^^^^
  File "/opt/venv/lib/python3.12/site-packages/sqlalchemy/orm/query.py", line 2808, in one
    return self._iter().one()  # type: ignore
           ^^^^^^^^^^^^^^^^^^^^^^^^^^^^^^^^^^
  File "/opt/venv/lib/python3.12/site-packages/sqlalchemy/orm/query.py", line 2857, in _iter
    result: Union[ScalarResult[_T], Result[_T]] = self.session.execute(
                                                  ^^^^^^^^^^^^^^^^^^^^^
  File "/opt/venv/lib/python3.12/site-packages/sqlalchemy/orm/session.py", line 2365, in execute
    return self._execute_internal(
           ^^^^^^^^^^^^^^^^^^^^^^^
  File "/opt/venv/lib/python3.12/site-packages/sqlalchemy/orm/session.py", line 2251, in _execute_internal
    result: Result[Any] = compile_state_cls.orm_execute_statement(
                          ^^^^^^^^^^^^^^^^^^^^^^^^^^^^^^^^^^^^^^^^
  File "/opt/venv/lib/python3.12/site-packages/sqlalchemy/orm/context.py", line 306, in orm_execute_statement
    result = conn.execute(
             ^^^^^^^^^^^^^
  File "/opt/venv/lib/python3.12/site-packages/sqlalchemy/engine/base.py", line 1419, in execute
    return meth(
           ^^^^^
  File "/opt/venv/lib/python3.12/site-packages/sqlalchemy/sql/elements.py", line 526, in _execute_on_connection
    return connection._execute_clauseelement(
           ^^^^^^^^^^^^^^^^^^^^^^^^^^^^^^^^^^
  File "/opt/venv/lib/python3.12/site-packages/sqlalchemy/engine/base.py", line 1641, in _execute_clauseelement
    ret = self._execute_context(
          ^^^^^^^^^^^^^^^^^^^^^^
  File "/opt/venv/lib/python3.12/site-packages/sqlalchemy/engine/base.py", line 1846, in _execute_context
    return self._exec_single_context(
           ^^^^^^^^^^^^^^^^^^^^^^^^^^
  File "/opt/venv/lib/python3.12/site-packages/sqlalchemy/engine/base.py", line 1986, in _exec_single_context
    self._handle_dbapi_exception(
  File "/opt/venv/lib/python3.12/site-packages/sqlalchemy/engine/base.py", line 2355, in _handle_dbapi_exception
    raise sqlalchemy_exception.with_traceback(exc_info[2]) from e
  File "/opt/venv/lib/python3.12/site-packages/sqlalchemy/engine/base.py", line 1967, in _exec_single_context
    self.dialect.do_execute(
  File "/opt/venv/lib/python3.12/site-packages/sqlalchemy/engine/default.py", line 951, in do_execute
    cursor.execute(statement, parameters)
sqlalchemy.exc.ProgrammingError: (psycopg2.errors.UndefinedColumn) column teacher.user_id does not exist
LINE 2: ...ne, teacher.observations AS teacher_observations, teacher.us...
                                                             ^

[SQL: SELECT count(*) AS count_1 
FROM (SELECT teacher.id AS teacher_id, teacher.name AS teacher_name, teacher.area AS teacher_area, teacher.subjects AS teacher_subjects, teacher.workload AS teacher_workload, teacher.email AS teacher_email, teacher.phone AS teacher_phone, teacher.observations AS teacher_observations, teacher.user_id AS teacher_user_id, teacher.created_at AS teacher_created_at 
FROM teacher) AS anon_1]
(Background on this error at: https://sqlalche.me/e/20/f405)
The debugger caught an exception in your WSGI application. You can now look at the traceback which led to the error.
To switch between the interactive traceback and the plaintext one, you can click on the "Traceback" headline. From the text traceback you can also create a paste of it.

Brought to you by D